<!-- 
Example MuJoCo XML model for an ant robot 
Save this file and use the path to it in your simulation code
-->

<mujoco model="ant">
    <compiler angle="degree" coordinate="local"/>
    <option timestep="0.01" gravity="0 0 -9.81" iterations="50" integrator="RK4"/>

    <worldbody>
        <!-- Floor -->
        <geom name="floor" type="plane" size="40 40 0.1" rgba="0.8 0.9 0.8 1"/>

        <!-- Ant body -->
        <body name="torso" pos="0 0 0.75">
            <geom name="torso_geom" type="sphere" size="0.25" rgba="0.8 0.3 0.3 1"/>
            <joint name="root" type="free"/>
            
            <!-- Front left leg -->
            <body name="front_left_leg" pos="0.2 0.2 -0.2">
                <joint name="front_left_hip" type="hinge" axis="0 1 0" range="-30 30"/>
                <geom name="front_left_leg_geom" type="capsule" fromto="0 0 0 0 0 -0.3" size="0.05"/>
                
                <body name="front_left_ankle" pos="0 0 -0.3">
                    <joint name="front_left_knee" type="hinge" axis="1 0 0" range="-30 30"/>
                    <geom name="front_left_foot_geom" type="capsule" fromto="0 0 0 0 0 -0.3" size="0.05"/>
                </body>
            </body>

            <!-- Front right leg -->
            <body name="front_right_leg" pos="0.2 -0.2 -0.2">
                <joint name="front_right_hip" type="hinge" axis="0 1 0" range="-30 30"/>
                <geom name="front_right_leg_geom" type="capsule" fromto="0 0 0 0 0 -0.3" size="0.05"/>
                
                <body name="front_right_ankle" pos="0 0 -0.3">
                    <joint name="front_right_knee" type="hinge" axis="1 0 0" range="-30 30"/>
                    <geom name="front_right_foot_geom" type="capsule" fromto="0 0 0 0 0 -0.3" size="0.05"/>
                </body>
            </body>

            <!-- Back left leg -->
            <body name="back_left_leg" pos="-0.2 0.2 -0.2">
                <joint name="back_left_hip" type="hinge" axis="0 1 0" range="-30 30"/>
                <geom name="back_left_leg_geom" type="capsule" fromto="0 0 0 0 0 -0.3" size="0.05"/>
                
                <body name="back_left_ankle" pos="0 0 -0.3">
                    <joint name="back_left_knee" type="hinge" axis="1 0 0" range="-30 30"/>
                    <geom name="back_left_foot_geom" type="capsule" fromto="0 0 0 0 0 -0.3" size="0.05"/>
                </body>
            </body>

            <!-- Back right leg -->
            <body name="back_right_leg" pos="-0.2 -0.2 -0.2">
                <joint name="back_right_hip" type="hinge" axis="0 1 0" range="-30 30"/>
                <geom name="back_right_leg_geom" type="capsule" fromto="0 0 0 0 0 -0.3" size="0.05"/>
                
                <body name="back_right_ankle" pos="0 0 -0.3">
                    <joint name="back_right_knee" type="hinge" axis="1 0 0" range="-30 30"/>
                    <geom name="back_right_foot_geom" type="capsule" fromto="0 0 0 0 0 -0.3" size="0.05"/>
                </body>
            </body>
        </body>
    </worldbody>

    <actuator>
        <motor joint="front_left_hip" ctrlrange="-1 1" ctrllimited="true"/>
        <motor joint="front_left_knee" ctrlrange="-1 1" ctrllimited="true"/>
        <motor joint="front_right_hip" ctrlrange="-1 1" ctrllimited="true"/>
        <motor joint="front_right_knee" ctrlrange="-1 1" ctrllimited="true"/>
        <motor joint="back_left_hip" ctrlrange="-1 1" ctrllimited="true"/>
        <motor joint="back_left_knee" ctrlrange="-1 1" ctrllimited="true"/>
        <motor joint="back_right_hip" ctrlrange="-1 1" ctrllimited="true"/>
        <motor joint="back_right_knee" ctrlrange="-1 1" ctrllimited="true"/>
    </actuator>
</mujoco>