<!-- <launch>
  <arg name="fake_execution_type" default="interpolate" />
  <param name="moveit_controller_manager" value="moveit_fake_controller_manager/MoveItFakeControllerManager"/>
  <rosparam subst_value="true" file="$(find ec63_moveit_config)/config/fake_controllers.yaml"/>
</launch> -->

<?xml version="1.0" encoding="utf-8"?>
<robot name="ec63">
    <link name="world" />
    <joint name="world_joint" type="fixed">
        <origin xyz="0 0 0" rpy="0 0 0" />
        <parent link="world" />
        <child link="base_link" />
    </joint>
    <link name="base_link">
    <inertial>
        <origin xyz="6.6025E-05 1.6931E-05 0.036471" rpy="0 0 0" />
        <mass value="0.3647" />
        <inertia ixx="0.00059057" ixy="6.2306E-07" ixz="6.6029E-07" iyy="0.00058934" iyz="-4.8028E-08"
            izz="0.00074656" />
    </inertial>
    <visual>
        <origin xyz="0 0 0" rpy="0 0 0" />
        <geometry>
            <mesh filename="package://elite_description/meshes/ec63/base_link.STL" />
        </geometry>
        <material name="">
            <color rgba="0.79216 0.81961 0.93333 1" />
        </material>
    </visual>
    <collision>
        <origin xyz="0 0 0" rpy="0 0 0" />
        <geometry>
            <mesh filename="package://elite_description/meshes/ec63/base_link.STL" />
        </geometry>
    </collision>
    </link>
    <link name="link1">
    <inertial>
        <origin xyz="-5.9693298609962E-07 0.00718798730554815 0.00130597011750025" rpy="0 0 0" />
        <mass value="1.0468989469595" />
        <inertia ixx="0.00131622835302873" ixy="1.33626024644229E-08" ixz="1.22267487012503E-08"
            iyy="0.00121041697616178" iyz="-0.000167494836949108" izz="0.00140200332966305" />
    </inertial>
    <visual>
        <origin xyz="0 0 0" rpy="0 0 0" />
        <geometry>
            <mesh filename="package://elite_description/meshes/ec63/link1.STL" />
        </geometry>
        <material name="">
            <color rgba="1 1 1 1" />
        </material>
    </visual>
    <collision>
        <origin xyz="0 0 0" rpy="0 0 0" />
        <geometry>
            <mesh filename="package://elite_description/meshes/ec63/link1.STL" />
        </geometry>
    </collision>
    </link>
    <joint name="joint1" type="revolute">
        <origin xyz="0 0 0.14" rpy="0 0 0" />
        <parent link="base_link" />
        <child link="link1" />
        <axis xyz="0 0 1" />
        <limit lower="-6.2832" upper="6.2832" effort="90" velocity="3.3161" />
    </joint>
</robot>