<?xml version="1.0" encoding="utf-8"?>
<!-- This URDF was automatically created by SolidWorks to URDF Exporter! Originally created by Stephen Brawner (brawner@gmail.com) 
     Commit Version: 1.6.0-1-g15f4949  Build Version: 1.6.7594.29634
     For more information, please see http://wiki.ros.org/sw_urdf_exporter -->
<robot
  name="ec66">
  <link
    name="base_link">
    <inertial>
      <origin
        xyz="0.000397608074828363 -1.29096807323018E-08 0.0126048532896169"
        rpy="0 0 0" />
      <mass
        value="1.11331791916805" />
      <inertia
        ixx="0.00146415393806588"
        ixy="-1.183188977766E-08"
        ixz="1.59388989762753E-06"
        iyy="0.00144024590571973"
        iyz="2.22170924273758E-11"
        izz="0.00277015131706661" />
    </inertial>
    <visual>
      <origin
        xyz="0 0 0"
        rpy="0 0 0" />
      <geometry>
        <mesh
          filename="package://ec66/meshes/base_link.STL" />
      </geometry>
      <material
        name="">
        <color
          rgba="0.898039215686275 0.917647058823529 0.929411764705882 1" />
      </material>
    </visual>
    <collision>
      <origin
        xyz="0 0 0"
        rpy="0 0 0" />
      <geometry>
        <mesh
          filename="package://ec66/meshes/base_link.STL" />
      </geometry>
    </collision>
  </link>
  <link
    name="baseJoint_Link">
    <inertial>
      <origin
        xyz="-2.47498315354449E-06 0.00826039958569003 0.0988378255398768"
        rpy="0 0 0" />
      <mass
        value="4.77747725763671" />
      <inertia
        ixx="0.00849289454076846"
        ixy="-5.32234800519548E-07"
        ixz="7.16578283706854E-08"
        iyy="0.00786131589240539"
        iyz="-0.00101643925063016"
        izz="0.00940237441881192" />
    </inertial>
    <visual>
      <origin
        xyz="0 0 0"
        rpy="0 0 0" />
      <geometry>
        <mesh
          filename="package://ec66/meshes/baseJoint_Link.STL" />
      </geometry>
      <material
        name="">
        <color
          rgba="1 1 1 1" />
      </material>
    </visual>
    <collision>
      <origin
        xyz="0 0 0"
        rpy="0 0 0" />
      <geometry>
        <mesh
          filename="package://ec66/meshes/baseJoint_Link.STL" />
      </geometry>
    </collision>
  </link>
  <joint
    name="baseJoint"
    type="revolute">
    <origin
      xyz="0 0 0"
      rpy="0 0 0" />
    <parent
      link="base_link" />
    <child
      link="baseJoint_Link" />
    <axis
      xyz="0 0 1" />
    <limit
      lower="-6.28"
      upper="6.28"
      effort="26"
      velocity="2.6" />
  </joint>
  <link
    name="shoulderJoint_Link">
    <inertial>
      <origin
        xyz="0.176379424035895 1.5979752906875E-06 0.139316565910418"
        rpy="0 0 0" />
      <mass
        value="13.090272465815" />
      <inertia
        ixx="0.0177158094414229"
        ixy="4.84272694421971E-07"
        ixz="-0.000567522549261307"
        iyy="0.0592307738592172"
        iyz="4.54387099656059E-07"
        izz="0.0603696439068193" />
    </inertial>
    <visual>
      <origin
        xyz="0 0 0"
        rpy="0 0 0" />
      <geometry>
        <mesh
          filename="package://ec66/meshes/shoulderJoint_Link.STL" />
      </geometry>
      <material
        name="">
        <color
          rgba="1 1 1 1" />
      </material>
    </visual>
    <collision>
      <origin
        xyz="0 0 0"
        rpy="0 0 0" />
      <geometry>
        <mesh
          filename="package://ec66/meshes/shoulderJoint_Link.STL" />
      </geometry>
    </collision>
  </link>
  <joint
    name="shoulderJoint"
    type="revolute">
    <origin
      xyz="0 0 0.096"
      rpy="-1.5708 0 0" />
    <parent
      link="baseJoint_Link" />
    <child
      link="shoulderJoint_Link" />
    <axis
      xyz="0 0 1" />
    <limit
      lower="-6.28"
      upper="6.28"
      effort="26"
      velocity="2.6" />
  </joint>
  <link
    name="elbowJoint_Link">
    <inertial>
      <origin
        xyz="0.20071 -8.4375E-06 0.028003"
        rpy="0 0 0" />
      <mass
        value="5.7608" />
      <inertia
        ixx="0.0042193"
        ixy="-1.2634E-07"
        ixz="0.00019659"
        iyy="0.024537"
        iyz="-4.4647E-07"
        izz="0.024537" />
    </inertial>
    <visual>
      <origin
        xyz="0 0 0"
        rpy="0 0 0" />
      <geometry>
        <mesh
          filename="package://ec66/meshes/elbowJoint_Link.STL" />
      </geometry>
      <material
        name="">
        <color
          rgba="1 1 1 1" />
      </material>
    </visual>
    <collision>
      <origin
        xyz="0 0 0"
        rpy="0 0 0" />
      <geometry>
        <mesh
          filename="package://ec66/meshes/elbowJoint_Link.STL" />
      </geometry>
    </collision>
  </link>
  <joint
    name="elbowJoint"
    type="revolute">
    <origin
      xyz="0.418 0 0"
      rpy="0 0 0" />
    <parent
      link="shoulderJoint_Link" />
    <child
      link="elbowJoint_Link" />
    <axis
      xyz="0 0 1" />
    <limit
      lower="-6.28"
      upper="6.28"
      effort="26"
      velocity="3.14" />
  </joint>
  <link
    name="wrist1Joint_Link">
    <inertial>
      <origin
        xyz="-1.0179E-06 -0.00072011 -0.006012"
        rpy="0 0 0" />
      <mass
        value="1.4325" />
      <inertia
        ixx="0.0011124"
        ixy="-3.2957E-08"
        ixz="-3.2784E-08"
        iyy="0.0011805"
        iyz="-0.00015657"
        izz="0.0010097" />
    </inertial>
    <visual>
      <origin
        xyz="0 0 0"
        rpy="0 0 0" />
      <geometry>
        <mesh
          filename="package://ec66/meshes/wrist1Joint_Link.STL" />
      </geometry>
      <material
        name="">
        <color
          rgba="1 1 1 1" />
      </material>
    </visual>
    <collision>
      <origin
        xyz="0 0 0"
        rpy="0 0 0" />
      <geometry>
        <mesh
          filename="package://ec66/meshes/wrist1Joint_Link.STL" />
      </geometry>
    </collision>
  </link>
  <joint
    name="wrist1Joint"
    type="revolute">
    <origin
      xyz="0.398 0 0.122"
      rpy="0 0 0" />
    <parent
      link="elbowJoint_Link" />
    <child
      link="wrist1Joint_Link" />
    <axis
      xyz="0 0 1" />
    <limit
      lower="-6.28"
      upper="6.28"
      effort="26"
      velocity="3.9" />
  </joint>
  <link
    name="wrist2Joint_Link">
    <inertial>
      <origin
        xyz="-1.0206E-06 -0.0007201 -0.006012"
        rpy="0 0 0" />
      <mass
        value="1.4325" />
      <inertia
        ixx="0.0011124"
        ixy="-3.2951E-08"
        ixz="-3.2928E-08"
        iyy="0.0011805"
        iyz="-0.00015657"
        izz="0.0010097" />
    </inertial>
    <visual>
      <origin
        xyz="0 0 0"
        rpy="0 0 0" />
      <geometry>
        <mesh
          filename="package://ec66/meshes/wrist2Joint_Link.STL" />
      </geometry>
      <material
        name="">
        <color
          rgba="1 1 1 1" />
      </material>
    </visual>
    <collision>
      <origin
        xyz="0 0 0"
        rpy="0 0 0" />
      <geometry>
        <mesh
          filename="package://ec66/meshes/wrist2Joint_Link.STL" />
      </geometry>
    </collision>
  </link>
  <joint
    name="wrist2Joint"
    type="revolute">
    <origin
      xyz="0 0.098 0"
      rpy="-1.5708 0 0" />
    <parent
      link="wrist1Joint_Link" />
    <child
      link="wrist2Joint_Link" />
    <axis
      xyz="0 0 1" />
    <limit
      lower="-6.28"
      upper="6.28"
      effort="26"
      velocity="3.9" />
  </joint>
  <link
    name="wrist3Joint_Link">
    <inertial>
      <origin
        xyz="-1.5919E-08 2.6113E-05 -0.021169"
        rpy="0 0 0" />
      <mass
        value="0.44188" />
      <inertia
        ixx="0.00020868"
        ixy="-1.5481E-09"
        ixz="-2.5463E-10"
        iyy="0.0002079"
        iyz="-2.0995E-07"
        izz="0.00031474" />
    </inertial>
    <visual>
      <origin
        xyz="0 0 0"
        rpy="0 0 0" />
      <geometry>
        <mesh
          filename="package://ec66/meshes/wrist3Joint_Link.STL" />
      </geometry>
      <material
        name="">
        <color
          rgba="0.89804 0.91765 0.92941 1" />
      </material>
    </visual>
    <collision>
      <origin
        xyz="0 0 0"
        rpy="0 0 0" />
      <geometry>
        <mesh
          filename="package://ec66/meshes/wrist3Joint_Link.STL" />
      </geometry>
    </collision>
  </link>
  <joint
    name="wrist3Joint"
    type="revolute">
    <origin
      xyz="0 0.089 0"
      rpy="-1.5708 0 0" />
    <parent
      link="wrist2Joint_Link" />
    <child
      link="wrist3Joint_Link" />
    <axis
      xyz="0 0 1" />
    <limit
      lower="-6.28"
      upper="6.28"
      effort="26"
      velocity="3.9" />
  </joint>
  <link name="brush">
    <inertial>
      <origin xyz="0.1175 -0.117 0.254315" rpy="-1.5708 0 0" />
      <mass value="0.2" />
      <inertia ixx="0.0001" ixy="0" ixz="0" iyy="0.0001" iyz="0" izz="0.0001" />
    </inertial>
    <visual>
      <origin xyz="0.1175 -0.117 0.254315" rpy="-1.5708 0 0" />
      <geometry>
        <mesh filename="package://ec66/meshes/brush.STL" scale = "0.001 0.001 0.001"/>
      </geometry>
      <material name="">
        <color rgba="0.5 0.5 0.5 1" />
      </material>
    </visual>
    <collision>
      <origin xyz="0.1175 -0.117 0.254315" rpy="-1.5708 0 0" />
      <geometry>
        <mesh filename="package://ec66/meshes/brush.STL" scale="0.001 0.001 0.001"/>
      </geometry>
    </collision>
  </link>
  <joint name="brush_joint" type="fixed">
    <origin xyz="0 0 0.53626" rpy="0 0 0" />
    <parent link="wrist3Joint_Link" />
    <child link="brush" />
  </joint>
</robot>
