<?xml version="1.0" encoding="utf-8"?>
<robot name="ec66">
  <link name="world" />
  <joint name="world_joint" type="fixed">
    <origin xyz="0 0 0" rpy="0 0 0" />
    <parent link="world" />
    <child link="base_link" />
  </joint>
  <link name="base_link">
  <inertial>
    <origin xyz="0.00039768 8.0247E-10 0.012605" rpy="0 0 0" />
    <mass value="0.41542" />
    <inertia ixx="0.00054632" ixy="-4.5067E-09" ixz="5.9528E-07" iyy="0.00053741" iyz="-3.5275E-10" izz="0.0010336" />
  </inertial>
  <visual>
    <origin xyz="0 0 0" rpy="0 0 0" />
    <geometry>
      <mesh filename="package://elite_description/meshes/ec66/base_link.STL" />
    </geometry>
    <material name="">
      <color rgba="0.89412 0.91373 0.92941 1" />
    </material>
  </visual>
  <collision>
    <origin xyz="0 0 0" rpy="0 0 0" />
    <geometry>
      <mesh filename="package://elite_description/meshes/ec66/base_link.STL" />
    </geometry>
  </collision>
  </link>
  <link name="link1">
  <inertial>
    <origin xyz="-3.9337E-06 0.0082614 0.0028405" rpy="0 0 0" />
    <mass value="1.7827" />
    <inertia ixx="0.0031691" ixy="-1.2175E-07" ixz="2.8351E-08" iyy="0.0029334" iyz="-0.00037927" izz="0.0035086" />
  </inertial>
  <visual>
    <origin xyz="0 0 0" rpy="0 0 0" />
    <geometry>
      <mesh filename="package://elite_description/meshes/ec66/link1.STL" />
    </geometry>
    <material name="">
      <color rgba="1 1 1 1" />
    </material>
  </visual>
  <collision>
    <origin xyz="0 0 0" rpy="0 0 0" />
    <geometry>
      <mesh filename="package://elite_description/meshes/ec66/link1.STL" />
    </geometry>
  </collision>
  </link>
  <joint name="joint1" type="revolute">
    <origin xyz="0 0 0.096" rpy="0 0 0" />
    <parent link="base_link" />
    <child link="link1" />
    <axis xyz="0 0 1" />
    <limit lower="-6.2832" upper="6.2832" effort="150" velocity="2.6199" />
  </joint>
  <link name="link2">
  <inertial>
    <origin xyz="-3.9632E-06 0.010506 -0.0056292" rpy="0 0 0" />
    <mass value="3.5947" />
    <inertia ixx="0.01211" ixy="-1.906E-07" ixz="-5.9544E-08" iyy="0.011358" iyz="-0.0010317" izz="0.012021" />
  </inertial>
  <visual>
    <origin xyz="0 0 0" rpy="0 0 0" />
    <geometry>
      <mesh filename="package://elite_description/meshes/ec66/link2.STL" />
    </geometry>
    <material name="">
      <color rgba="1 1 1 1" />
    </material>
  </visual>
  <collision>
    <origin xyz="0 0 0" rpy="0 0 0" />
    <geometry>
      <mesh filename="package://elite_description/meshes/ec66/link2.STL" />
    </geometry>
  </collision>
  </link>
  <joint name="joint2" type="revolute">
    <origin xyz="0 0 0.185" rpy="0 0 0" />
    <parent link="link1" />
    <child link="link2" />
    <axis xyz="0 0 1" />
    <limit lower="-6.2832" upper="6.2832" effort="200" velocity="2.0944" />
  </joint>
</robot>